<?xml version="1.0"?>
<robot xmlns:xacro="http://www.ros.org/wiki/xacro" name="mobile_robot">

  <link name="base_link">
  </link>

  <xacro:property name="height" value="0.4" />
  <xacro:property name="width" value="0.4" />
  <xacro:property name="depth" value="0.1" />

  <link name="chassis">
    <visual>
      <geometry>
        <box size="${height} ${width} ${depth}"/>
      </geometry>
    </visual>
    <collision>
      <geometry>
        <box size="${height} ${width} ${depth}"/>
      </geometry>
    </collision>
    <inertial>
      <mass value="5.0"/> <inertia ixx="0.1" ixy="0.0" ixz="0.0" iyy="0.1" iyz="0.0" izz="0.1"/>
    </inertial>
  </link>

  <gazebo reference="chassis">
    <material>Gazebo/Red</material>
  </gazebo>

  <joint name="chassis_joint" type="fixed">
    <parent link="base_link"/>
    <child link="chassis"/>
  </joint>

  <material name="blue">
    <color rgba="0 0 0.8 1"/>
  </material>

  <xacro:property name="wheel_height" value="0.04" />
  <xacro:property name="wheel_radius" value="0.06" />

  <xacro:macro name="wheel" params="name reflect_x reflect_y reflect_r reflect_axis">
    
    <link name="${name}_wheel">
      <visual>
        <geometry>
          <cylinder length="${wheel_height}" radius="${wheel_radius}"/>
        </geometry>
        <material name="blue"/>
      </visual>
      <collision>
        <geometry>
          <cylinder length="${wheel_height}" radius="${wheel_radius}"/>
        </geometry>
      </collision>
      <inertial>
        <mass value="0.5"/> 
        <inertia ixx="0.001" ixy="0.0" ixz="0.0" iyy="0.001" iyz="0.0" izz="0.001"/>
      </inertial>
    </link>

    <joint name="${name}_wheel_joint" type="continuous">
      <parent link="chassis"/>
      <child link="${name}_wheel"/>
      <origin xyz="${reflect_x*height/2} ${reflect_y*(width/2+0.025)} -0.05" rpy="${reflect_r*1.5707} 0 0"/>
      <axis xyz="0 0 ${reflect_axis}"/>
    </joint>

    <gazebo reference="${name}_wheel">
      <material>Gazebo/Blue</material>
    </gazebo>

  </xacro:macro>

  <xacro:wheel name="front_right" reflect_x="1" reflect_y="-1" reflect_r="1" reflect_axis="-1"/>
  <xacro:wheel name="front_left" reflect_x="1" reflect_y="1" reflect_r="-1" reflect_axis="1"/>
  <xacro:wheel name="rear_right" reflect_x="-1" reflect_y="-1" reflect_r="1" reflect_axis="-1"/>
  <xacro:wheel name="rear_left" reflect_x="-1" reflect_y="1" reflect_r="-1" reflect_axis="1"/>

  <material name="green">
    <color rgba="0 0.8 0 1"/>
  </material>

  <link name="head">
    <visual>
      <geometry>
        <box size="0.04 0.04 0.04"/>
      </geometry>
      <material name="green"/>
    </visual>
  </link>

  <joint name="head_joint" type="fixed">
    <parent link="chassis"/>
    <child link="head"/>
    <origin xyz="0.1 0 0.07" rpy="0 0 0"/>
  </joint>

  <gazebo reference="head">
    <material>Gazebo/Green</material>
  </gazebo>

  <gazebo>
    <plugin name="skid_steer_drive_controller" filename="libgazebo_ros_skid_steer_drive.so">
      <updateRate>100.0</updateRate>
      <robotNamespace>/</robotNamespace>
      
      <leftFrontJoint>front_left_wheel_joint</leftFrontJoint>
      <rightFrontJoint>front_right_wheel_joint</rightFrontJoint>
      <leftRearJoint>rear_left_wheel_joint</leftRearJoint>
      <rightRearJoint>rear_right_wheel_joint</rightRearJoint>

      <wheelSeparation>0.4</wheelSeparation>
      <wheelDiameter>0.12</wheelDiameter>
      
      <torque>20</torque>
      
      <commandTopic>cmd_vel</commandTopic>
      <odometryTopic>odom</odometryTopic>
      <odometryFrame>odom</odometryFrame>
      <robotBaseFrame>base_link</robotBaseFrame>
      
      <broadcastTF>true</broadcastTF>
    </plugin>
  </gazebo>

</robot>