<?xml version="1.0"?>
<robot xmlns:xacro="http://www.ros.org/wiki/xacro" >

    <xacro:include filename="inertial_macros.xacro"/>

    <material name="white"><color rgba="1 1 1 1" /></material>
    <material name="orange"><color rgba="1 0.3 0.1 1"/></material>
    <material name="blue"><color rgba="0.2 0.2 1 1"/></material>
    <material name="black"><color rgba="0 0 0 1"/></material>
    <material name="red"><color rgba="1 0 0 1"/></material>

    <link name="base_link"></link>

    <joint name="chassis_joint" type="fixed">
        <parent link="base_link"/>
        <child link="chassis"/>
        <origin xyz="-0.1 0 0"/>
    </joint>

    <link name="chassis">
        <visual>
            <origin xyz="0.15 0 0.075"/>
            <geometry>
                <box size="0.3 0.3 0.15"/>
            </geometry>
            <material name="white"/>
        </visual>
        <collision>
            <origin xyz="0.15 0 0.075"/>
            <geometry>
                <box size="0.3 0.3 0.15"/>
            </geometry>
        </collision>
        <xacro:inertial_box mass="0.5" x="0.3" y="0.3" z="0.15">
            <origin xyz="0.15 0 0.075" rpy="0 0 0"/>
        </xacro:inertial_box>
    </link>
    
    <gazebo reference="chassis">
        <material>Gazebo/White</material>
    </gazebo>

    <xacro:macro name="wheel" params="prefix x_reflect y_reflect">
        <link name="${prefix}_wheel">
            <visual>
                <geometry>
                    <cylinder radius="0.05" length="0.04"/>
                </geometry>
                <material name="blue"/>
            </visual>
            <collision>
                <geometry>
                    <cylinder radius="0.05" length="0.04"/>
                </geometry>
            </collision>
            <xacro:inertial_cylinder mass="0.1" length="0.04" radius="0.05">
                <origin xyz="0 0 0" rpy="0 0 0"/>
            </xacro:inertial_cylinder>
        </link>

        <joint name="${prefix}_wheel_joint" type="continuous">
            <parent link="base_link"/>
            <child link="${prefix}_wheel"/>
            <origin xyz="${x_reflect*0.1} ${y_reflect*0.175} 0" rpy="-${pi/2} 0 0"/>
            <axis xyz="0 0 1"/>
        </joint>

        <gazebo reference="${prefix}_wheel">
            <material>Gazebo/Blue</material>
            <mu1>0.2</mu1>
            <mu2>0.4</mu2>
        </gazebo>
    </xacro:macro>

    <xacro:wheel prefix="front_left" x_reflect="1" y_reflect="1" />
    <xacro:wheel prefix="front_right" x_reflect="1" y_reflect="-1" />
    <xacro:wheel prefix="rear_left" x_reflect="-1" y_reflect="1" />
    <xacro:wheel prefix="rear_right" x_reflect="-1" y_reflect="-1" />


</robot>